<!--?xml version="1.0" encoding="utf-8"?-->
<!-- This URDF was automatically created by SolidWorks to URDF Exporter! Originally created by Stephen Brawner (brawner@gmail.com) 
     Commit Version: 1.6.0-1-g15f4949  Build Version: 1.6.7594.29634
     For more information, please see http://wiki.ros.org/sw_urdf_exporter -->
<!--robot name="robot"-->
<robot xmlns:xacro="http://www.ros.org/wiki/xacro" name="mobile_robot">
  <link name="base_link">
    <inertial>
      <origin xyz="0.0069473 1.6133E-06 -0.0058463" rpy="0 0 0" />
      <mass value="0.12" />
      <inertia 
        ixx="0.0001"
        ixy="0"
        ixz="0"
        iyy="0.0003"
        iyz="0"
        izz="0.0002"  />
    </inertial>
    <visual>
      <origin xyz="0 0 0" rpy="0 0 0" />
      <geometry>
        <mesh filename="package://robot/meshes/base_link.STL" />
      </geometry>
      <material name="">
        <color rgba="0.38824 0.85882 0.38824 0.3" />
      </material>
    </visual>
    <collision>
      <origin xyz="0 0 0" rpy="0 0 0" />
      <geometry>
        <mesh filename="package://robot/meshes/base_link.STL" />
      </geometry>
    </collision>
  </link>
  
  <gazebo reference="base_link">
    <mu1>200</mu1>
    <mu2>200</mu2>
    <kp>1000000</kp>
    <kd>1</kd>
    <material>Gazebo/Green</material>
  </gazebo>
  
  <link name="Rueda_Izquierda_Link">
    <inertial>
      <origin xyz="7.6328E-16 -8.3267E-17 -0.0013855" rpy="0 0 0" />
      <mass value="0.1403" />
      <inertia
        ixx="0.000037815"
        ixy="0"
        ixz="0"
        iyy="0.000037816"
        iyz="0"
        izz="0.000074346" />
    </inertial>
    <visual>
      <origin xyz="0 0 0" rpy="0 0 0" />
      <geometry>
        <mesh filename="package://robot/meshes/Rueda_Izquierda_Link.STL" />
      </geometry>
      <material name="">
        <color rgba="0.98431 1 0.18431 1" />
      </material>
    </visual>
    <collision>
      <origin xyz="0 0 0" rpy="0 0 0" />
      <geometry>
        <mesh filename="package://robot/meshes/Rueda_Izquierda_Link.STL" />
      </geometry>
    </collision>
  </link>
  
  <joint name="Rueda_Izquierda_joint" type="continuous">
    <origin xyz="-0.0037465 0.059006 -0.015799" rpy="-1.5708 0 0" />
    <parent link="base_link" />
    <child link="Rueda_Izquierda_Link" />
    <axis xyz="0 0 1" />
    <limit effort="100" velocity="100" />
    <dynamics damping="0.1" friction="0.1" />
  </joint>
  
  <gazebo reference="Rueda_Izquierda_Link">
    <mu1>200</mu1>
    <mu2>200</mu2>
    <kp>1000000</kp>
    <kd>1</kd>
    <material>Gazebo/Yellow</material>
  </gazebo>
  
  <link name="Rueda_Derecha_Link">
    <inertial>
      <origin xyz="-7.494E-16 -8.3267E-17 0.0013855" rpy="0 0 0" />
      <mass value="0.1403" />
      <inertia
        ixx="0.000037815"
        ixy="0"
        ixz="0"
        iyy="0.000037816"
        iyz="0"
        izz="0.000074346" />
    </inertial>
    <visual>
      <origin xyz="0 0 0" rpy="0 0 0" />
      <geometry>
        <mesh filename="package://robot/meshes/Rueda_Derecha_Link.STL" />
      </geometry>
      <material name="">
        <color rgba="0.98431 1 0.18431 1" />
      </material>
    </visual>
    <collision>
      <origin xyz="0 0 0" rpy="0 0 0" />
      <geometry>
        <mesh filename="package://robot/meshes/Rueda_Derecha_Link.STL" />
      </geometry>
    </collision>
  </link>
  <joint name="Rueda_Derecha_joint" type="continuous">
    <origin xyz="-0.0037465 -0.058994 -0.015799" rpy="1.5708 0 3.1416" />
    <parent link="base_link" />
    <child link="Rueda_Derecha_Link" />
    <axis xyz="0 0 1" />
    <limit effort="100" velocity="100" />
    <dynamics damping="0.1" friction="0.1" />
  </joint>
  
  <gazebo reference="Rueda_Derecha_Link">
    <mu1>200</mu1>
    <mu2>200</mu2>
    <kp>1000000</kp>
    <kd>1</kd>
    <material>Gazebo/Yellow</material>
  </gazebo>
  
  <link name="Base_castor_Link">
    <inertial>
      <origin xyz="7.2582E-05 6.9389E-18 0.022644" rpy="0 0 0" />
      <mass value="0.5" />
      <inertia
        ixx="0.000004521"
        ixy="0"
        ixz="0"
        iyy="0.0000024423"
        iyz="0"
        izz="0.0000035365" />
    </inertial>
    <visual>
      <origin xyz="0 0 0" rpy="0 0 0" />
      <geometry>
        <mesh filename="package://robot/meshes/Base_castor_Link.STL" />
      </geometry>
      <material name="">
        <color rgba="0.79216 0.81961 0.93333 1" />
      </material>
    </visual>
    <collision>
      <origin xyz="0 0 0" rpy="0 0 0" />
      <geometry>
        <mesh filename="package://robot/meshes/Base_castor_Link.STL" />
      </geometry>
    </collision>
  </link>
  <joint name="Base_castor_joint" type="continuous">
    <origin xyz="0.051854 0 -0.008" rpy="-3.1416 0 0" />
    <parent link="base_link" />
    <child link="Base_castor_Link" />
    <axis xyz="0 0 1" />
    <limit effort="100" velocity="100" />
    <!--dynamics damping="0.1" friction="0.1" /-->
  </joint>
  
  <gazebo reference="Base_castor_Link">
    <mu1>0.1</mu1>
    <mu2>0.1</mu2>
    <kp>1000000</kp>
    <kd>1</kd>
    <material>Gazebo/Gray</material>
  </gazebo>
  
  <link name="Rueda_Castor_Link">
    <inertial>
      <origin xyz="0 1.7347E-18 0" rpy="0 0 0" />
      <mass value="0.0828739992319076" />
      <inertia
        ixx="0.0000085831"
        ixy="0"
        ixz="0"
        iyy="0.0000085831"
        iyz="0"
        izz="0.000013936" />
    </inertial>
    <visual>
      <origin xyz="0 0 0" rpy="0 0 0" />
      <geometry>
        <mesh filename="package://robot/meshes/Rueda_Castor_Link.STL" />
      </geometry>
      <material name="">
        <color rgba="0.79216 0.81961 0.93333 1" />
      </material>
    </visual>
    <collision>
      <origin xyz="0 0 0" rpy="0 0 0" />
      <geometry>
        <mesh filename="package://robot/meshes/Rueda_Castor_Link.STL" />
      </geometry>
    </collision>
  </link>
  <joint name="Rueda_Castor_joint" type="continuous">
    <origin xyz="0 0.0005 0.026988" rpy="1.5708 -1.5708 0" />
    <parent link="Base_castor_Link" />
    <child link="Rueda_Castor_Link" />
    <axis xyz="0 0 1" />
    <limit effort="100" velocity="100" />
    <!--dynamics damping="0.05" friction="0.05" /-->
  </joint>
  
  <gazebo reference="Rueda_Castor_Link">
    <mu1>0.1</mu1>
    <mu2>0.1</mu2>
    <kp>1000000</kp>
    <kd>1</kd>
    <material>Gazebo/Orange</material>
  </gazebo>
  

  <link name="Lidar_link">
  <inertial>
    <origin xyz="0 0 0.0" rpy="0 0 0.0"/>
    <mass value="0.01"/>
    <inertia ixx="0.0001"  ixy="0"  ixz="0" iyy="0.0001" iyz="0" izz="0.0001" />
  </inertial>
  <visual>
    <origin xyz="0 0 0" rpy="0 0 0"/>
    <geometry>
       <cylinder radius="0.01" length="0.05"/>
    </geometry>
    <material
      name="">
      <color
        rgba="1 1 0 0.5" />
    </material>
  </visual>
  <collision>
    <origin xyz="0 0 0.0" rpy="0 0 0"/>
    <geometry>
       <cylinder radius="0.01" length="0.05"/>
    </geometry>
    <material
      name="">
      <color
        rgba="1 1 1 0.5" />
    </material>
  </collision>
  </link>


  <joint
    name="Lidar_joint"
    type="fixed">
    <origin
      xyz="0.0 0 0.02"
      rpy="0 -0.04 0" /> <!-- Disminuye la inclinación a -0.04 radianes -->
    <parent
      link="base_link" />
    <child
      link="Lidar_link" />
    <axis
      xyz="1 0 0" />
  </joint>

  
  <link name="imu_link"/>
  <joint
    name="imu_joint"
    type="fixed">
    <origin
      xyz="0.0 0 0.0"
      rpy="0 0 0" />
    <parent
      link="base_link" />
    <child
      link="imu_link" />
    <axis
      xyz="1 0 0" />
  </joint>


  <!--LIDAR CONFIGURATION-->

  <gazebo reference="Lidar_link">
    <sensor name="lidar" type="ray">
        <always_on>true</always_on>
        <visualize>true</visualize>
        <update_rate>20</update_rate>
        <ray>
            <scan>
                <horizontal>
                    <samples>360</samples>
                    <resolution>1.000000</resolution>
                    <min_angle>-3.1416</min_angle> <!-- -90 grados -->
                    <max_angle>3.1416</max_angle>  <!-- 90 grados -->
                </horizontal>
            </scan>
            <range>
                <min>0.07</min>
                <max>1.5</max> <!-- Distancia máxima reducida a la mitad -->
                <resolution>0.015</resolution>
            </range>
            <noise>
                <type>gaussian</type>
                <mean>0.0</mean>
                <stddev>0.01</stddev>
            </noise>
        </ray>
        <plugin name="scan" filename="libgazebo_ros_ray_sensor.so">
            <ros>
                <remapping>~/out:=laser_scan</remapping>
            </ros>
            <output_type>sensor_msgs/LaserScan</output_type>
            <frame_name>Lidar_link</frame_name>
        </plugin>
    </sensor>
</gazebo>



  <gazebo reference="Lidar_link">
    <mu1>0.1</mu1>
    <mu2>0.1</mu2>
    <kp>1000000</kp>
    <kd>1</kd>
    <material>Gazebo/Yellow</material>
  </gazebo>

   <!--IMU sensor-->

  <gazebo reference="imu_link">
    <gravity>true</gravity>
    <sensor name="imu_sensor" type="imu">
      <always_on>true</always_on>
      <update_rate>100</update_rate>
      <visualize>true</visualize>
      <topic>imu_data</topic>
      <plugin filename="libgazebo_ros_imu_sensor.so" name="imu_plugin">
        <topicName>imu_data</topicName>
        <bodyName>imu_link</bodyName>
        <updateRateHZ>10.0</updateRateHZ>
        <gaussianNoise>0.005</gaussianNoise>
        <xyzOffset>0 0 0</xyzOffset>
        <rpyOffset>0 0 0</rpyOffset>
        <frameName>imu_link</frameName>
        <initialOrientationAsReference>true</initialOrientationAsReference>
      </plugin>
      <pose>0 0 0 0 0 0</pose>
    </sensor>
  </gazebo>
  
  <!-- ESTA PARTE ES LA DE MOVIMIENTO -->
  <gazebo>
    <plugin name="two_wheeled_robot_diff_drive" filename="libgazebo_ros_diff_drive.so">
 
      <update_rate>100</update_rate>
      
      <!-- wheels -->
      <left_joint>Rueda_Izquierda_joint</left_joint>
      <right_joint>Rueda_Derecha_joint</right_joint>
 
      <!-- kinematics -->
      <wheel_separation>0.15</wheel_separation>
      <wheel_diameter>0.06</wheel_diameter>
 
      <!-- limits -->
      <max_wheel_torque>20</max_wheel_torque>
      <max_wheel_acceleration>20.0</max_wheel_acceleration>
 
      <!-- Receive velocity commands on this ROS topic -->
      <command_topic>cmd_vel</command_topic>
 
      <!-- output -->
      <!-- When false, publish no wheel odometry data to a ROS topic -->
      <publish_odom>true</publish_odom>
 
      <!-- When true, publish coordinate transform from odom to base_footprint -->
      <!-- I usually use the robot_localization package to publish this transform -->  
      <publish_odom_tf>true</publish_odom_tf>
     
      <!-- When true, publish coordinate transform from base_link to the wheels -->
      <!-- The robot_state_publisher package is often used to publish this transform -->  
      <publish_wheel_tf>true</publish_wheel_tf>
 
      <odometry_topic>odom</odometry_topic>
      <odometry_frame>odom_link</odometry_frame>
      <robot_base_frame>base_link</robot_base_frame>
 
      <odometry_source>1</odometry_source>
      <ros>
        <remapping>odom:=wheel/odometry</remapping>
      </ros>
    </plugin>
  </gazebo>

  <gazebo>
    <plugin name="gazebo_ros_joint_state_publisher"
        filename="libgazebo_ros_joint_state_publisher.so">
        <update_rate>100</update_rate>
        <joint_name>Base_castor_joint</joint_name>
        <joint_name>Rueda_Castor_joint</joint_name>
    </plugin>
  </gazebo>
  
</robot>
